Workbook

Sheet Oferta
A1: FAPO POLSKA
A2: Katalog części i kalkulacja oferty
A4: Data przygotowania | B4: 2026-05-25
A5: Liczba produktów w katalogu | B5: 629
A6: Waluta | B6: PLN
A7: Źródło danych | B7: assets/data/products.json
A8: Kontakt handlowy | B8: office@fapomoto.pl | info@fapomoto.pl
A9: Kalkulacja klienta | B9: Wartość
A10: Wybrane pozycje | B10: =COUNTIF('Katalog i kalkulacja'!$I$2:$I$630,">0")
A11: Łączna ilość | B11: =SUM('Katalog i kalkulacja'!$I$2:$I$630)
A12: Suma katalogowa PLN | B12: =SUMPRODUCT('Katalog i kalkulacja'!$F$2:$F$630,'Katalog i kalkulacja'!$I$2:$I$630)
A13: Suma po rabatach PLN | B13: =SUM('Katalog i kalkulacja'!$J$2:$J$630)
A16: Kategoria | B16: Liczba produktów | C16: Cena min PLN | D16: Cena średnia PLN | E16: Cena max PLN | F16: Wartość wybrana PLN
A17: Chassis | B17: 20 | C17: 184 | D17: 588.15 | E17: 2312 | F17: =SUMIF('Katalog i kalkulacja'!$D:$D,A17,'Katalog i kalkulacja'!$J:$J)
A18: Coilovers | B18: 397 | C18: 66 | D18: 1994.37 | E18: 6284 | F18: =SUMIF('Katalog i kalkulacja'!$D:$D,A18,'Katalog i kalkulacja'!$J:$J)
A19: Exhaust | B19: 52 | C19: 232 | D19: 1228.6 | E19: 3305 | F19: =SUMIF('Katalog i kalkulacja'!$D:$D,A19,'Katalog i kalkulacja'!$J:$J)
A20: Off-Road | B20: 120 | C20: 184 | D20: 767.28 | E20: 3310 | F20: =SUMIF('Katalog i kalkulacja'!$D:$D,A20,'Katalog i kalkulacja'!$J:$J)
A21: Performance | B21: 20 | C21: 170 | D21: 1134.7 | E21: 3778 | F21: =SUMIF('Katalog i kalkulacja'!$D:$D,A21,'Katalog i kalkulacja'!$J:$J)
A22: Turbo | B22: 20 | C22: 137 | D22: 2210.85 | E22: 4251 | F22: =SUMIF('Katalog i kalkulacja'!$D:$D,A22,'Katalog i kalkulacja'!$J:$J)

Sheet Katalog i kalkulacja
A1: LP | B1: ID | C1: SKU | D1: Kategoria | E1: Nazwa produktu | F1: Cena katalogowa PLN | G1: Rabat % | H1: Cena po rabacie PLN | I1: Ilość | J1: Wartość PLN | K1: Link produktu FAPO PL | L1: Link zdjęcia | M1: Liczba zdjęć | N1: Źródło | O1: Uwagi
A2: 1 | B2: p0144 | C2: FZ009010 | D2: Chassis | E2: Rear Camber Lateral Control Arm FOR 02-07 93-01 IMPREZA WRX STi GD/GG 6PCS FZ009010 | F2: 1272 | G2: 0 | H2: =ROUND(F2*(1-G2),2) | I2: 0 | J2: =ROUND(H2*I2,2) | K2: https://fapomoto.pl/produkty/p0144-fz009010-rear-camber-lateral-control-arm-for-02-07-93-01-impreza-wrx-sti-gd-gg-6pcs-fz009010.html | L2: https://cdn.shopify.com/s/files/1/0764/7258/2395/files/687cba68d798e4bd.jpg?v=1751438190 | M2: 8 | N2: fapomoto
A3: 2 | B3: p0086 | C3: FZ031010 | D3: Chassis | E3: Front Extended Stainless Steel Brake Lines For Ford F-150 XLT Bronco 1980-1996 | F3: 184 | G3: 0 | H3: =ROUND(F3*(1-G3),2) | I3: 0 | J3: =ROUND(H3*I3,2) | K3: https://fapomoto.pl/produkty/p0086-fz031010-front-extended-stainless-steel-brake-lines-for-ford-f-150-xlt-bronco-1980-1996.html | L3: https://cdn.shopify.com/s/files/1/0764/7258/2395/files/f2019038e1923bfb.jpg?v=1751436475 | M3: 3 | N3: fapomoto
A4: 3 | B4: p0088 | C4: FZ033010 | D4: Chassis | E4: Rear Extended Stainless Steel Brake Line For Ford F-150 XLT Bronco 1980-1996 | F4: 184 | G4: 0 | H4: =ROUND(F4*(1-G4),2) | I4: 0 | J4: =ROUND(H4*I4,2) | K4: https://fapomoto.pl/produkty/p0088-fz033010-rear-extended-stainless-steel-brake-line-for-ford-f-150-xlt-bronco-1980-1996.html | L4: https://cdn.shopify.com/s/files/1/0764/7258/2395/files/49c3b012df6f1e4d.jpg?v=1751436493 | M4: 3 | N4: fapomoto
A5: 4 | B5: p0084 | C5: FZ034010 | D5: Chassis | E5: FAPO Front 4-6" Extended Brake Lines For Chevy C K 10 20 30 K5 Blazer 1971-1978 | F5: 232 | G5: 0 | H5: =ROUND(F5*(1-G5),2) | I5: 0 | J5: =ROUND(H5*I5,2) | K5: https://fapomoto.pl/produkty/p0084-fz034010-fapo-front-4-6-extended-brake-lines-for-chevy-c-k-10-20-30-k5-blazer-1971-1978.html | L5: https://cdn.shopify.com/s/files/1/0764/7258/2395/files/b49220ac45a6a65e.jpg?v=1751436466 | M5: 3 | N5: fapomoto
A6: 5 | B6: p0579 | C6: FZ042640 | D6: Chassis | E6: FAPO Front Lower Control Arms for Honda Civic EG/EH/EJ 1992-1995 Integra DC2 1994-2001 FZ042640 | F6: 563 | G6: 0 | H6: =ROUND(F6*(1-G6),2) | I6: 0 | J6: =ROUND(H6*I6,2) | K6: https://fapomoto.pl/produkty/p0579-fz042640-fapo-front-lower-control-arms-for-honda-civic-eg-eh-ej-1992-1995-integra-dc2-1994-2001-fz042640.html | L6: https://cdn.shopify.com/s/files/1/0764/7258/2395/files/FZ042640_1.jpg?v=1773295182 | M6: 8 | N6: fapomoto
A7: 6 | B7: p0578 | C7: FZ042670 | D7: Chassis | E7: FAPO Front Lower Control Arms for Honda Civic EG/EH/EJ 92-95 Integra DC2 94-01 FZ042670 | F7: 563 | G7: 0 | H7: =ROUND(F7*(1-G7),2) | I7: 0 | J7: =ROUND(H7*I7,2) | K7: https://fapomoto.pl/produkty/p0578-fz042670-fapo-front-lower-control-arms-for-honda-civic-eg-eh-ej-92-95-integra-dc2-94-01-fz042670.html | L7: https://cdn.shopify.com/s/files/1/0764/7258/2395/files/FZ042670_1.jpg?v=1773294945 | M7: 8 | N7: fapomoto
A8: 7 | B8: p0075 | C8: FZ071310 | D8: Chassis | E8: Rear Extended Stainless Steel Brake Line For Ford F-250 F-350 Super Duty 99-04 | F8: 184 | G8: 0 | H8: =ROUND(F8*(1-G8),2) | I8: 0 | J8: =ROUND(H8*I8,2) | K8: https://fapomoto.pl/produkty/p0075-fz071310-rear-extended-stainless-steel-brake-line-for-ford-f-250-f-350-super-duty-99-04.html | L8: https://cdn.shopify.com/s/files/1/0764/7258/2395/files/a7a5986997151216.jpg?v=1751436391 | M8: 3 | N8: fapomoto
A9: 8 | B9: p0591 | C9: PZ001120 | D9: Chassis | E9: FAPO Rear Adjustable Lower Control Arm kit for Nissan S14 S15 240SX 200SX PZ001120 | F9: 894 | G9: 0 | H9: =ROUND(F9*(1-G9),2) | I9: 0 | J9: =ROUND(H9*I9,2) | K9: https://fapomoto.pl/produkty/p0591-pz001120-fapo-rear-adjustable-lower-control-arm-kit-for-nissan-s14-s15-240sx-200sx-pz001120.html | L9: https://cdn.shopify.com/s/files/1/0764/7258/2395/files/PZ001120_1.jpg?v=1773976223 | M9: 8 | N9: fapomoto
A10: 9 | B10: p0573 | C10: PZ002810 | D10: Chassis | E10: Black Rear Lower Control Arms for 88-95 Honda Civic EF9 EG6 94-01 Integra PZ002810 | F10: 515 | G10: 0 | H10: =ROUND(F10*(1-G10),2) | I10: 0 | J10: =ROUND(H10*I10,2) | K10: https://fapomoto.pl/produkty/p0573-pz002810-black-rear-lower-control-arms-for-88-95-honda-civic-ef9-eg6-94-01-integra-pz002810.html | L10: https://cdn.shopify.com/s/files/1/0764/7258/2395/files/PZ002810_1.jpg?v=1773293036 | M10: 6 | N10: fapomoto
A11: 10 | B11: p0062 | C11: PZ006110 | D11: Chassis | E11: Rear Adjustable Camber Arm For 92-06 BMW 3- Series E36 E46 X3 E83 04-10 PZ006110 | F11: 402 | G11: 0 | H11: =ROUND(F11*(1-G11),2) | I11: 0 | J11: =ROUND(H11*I11,2) | K11: https://fapomoto.pl/produkty/p0062-pz006110-rear-adjustable-camber-arm-for-92-06-bmw-3-series-e36-e46-x3-e83-04-10-pz006110.html | L11: https://cdn.shopify.com/s/files/1/0764/7258/2395/files/de3d2cd3c7b24483.jpg?v=1751435528 | M11: 6 | N11: fapomoto
A12: 11 | B12: p0089 | C12: PZ006210 | D12: Chassis | E12: Fapo E36 Angle Kit Drift Front Lower Control Arm for BMW E36 PZ006210 | F12: 2312 | G12: 0 | H12: =ROUND(F12*(1-G12),2) | I12: 0 | J12: =ROUND(H12*I12,2) | K12: https://fapomoto.pl/produkty/p0089-pz006210-fapo-e36-angle-kit-drift-front-lower-control-arm-for-bmw-e36-pz006210.html | L12: https://cdn.shopify.com/s/files/1/0764/7258/2395/files/a765d0a8cfa7b0db.jpg?v=1751436500 | M12: 6 | N12: fapomoto
A13: 12 | B13: p0065 | C13: PZ006310 | D13: Chassis | E13: Front Steering Drift Lower Control Arm Wide Angle Kit For BMW E46 PZ006310 | F13: 2123 | G13: 0 | H13: =ROUND(F13*(1-G13),2) | I13: 0 | J13: =ROUND(H13*I13,2) | K13: https://fapomoto.pl/produkty/p0065-pz006310-front-steering-drift-lower-control-arm-wide-angle-kit-for-bmw-e46-pz006310.html | L13: https://cdn.shopify.com/s/files/1/0764/7258/2395/files/f2ca558a09cce77e.jpg?v=1756367177 | M13: 8 | N13: fapomoto
... A15: 14 | B15: p0577 | C15: PZ282010 | D15: Chassis | E15: Front Stabilizer Sway Bar End Link For Mercedes Benz W203 2000-07 CLK W209 2002-2009 PZ282010 | F15: 260 | G15: 0 | H15: =ROUND(F15*(1-G15),2) | I15: 0 | J15: =ROUND(H15*I15,2) | K15: https://fapomoto.pl/produkty/p0577-pz282010-front-stabilizer-sway-bar-end-link-for-mercedes-benz-w203-2000-07-clk-w209-2002-2009-pz282010.html | L15: https://cdn.shopify.com/s/files/1/0764/7258/2395/files/DSC03831.jpg?v=1773294486 | M15: 4 | N15: fapomoto
A16: 15 | B16: p0206 | C16: PZ282510 | D16: Chassis | E16: Front Stabilizer Sway Bar End Links For Honda civic 12-15 Mini Cooper R56 06-13 | F16: 255 | G16: 0 | H16: =ROUND(F16*(1-G16),2) | I16: 0 | J16: =ROUND(H16*I16,2) | K16: https://fapomoto.pl/produkty/p0206-pz282510-front-stabilizer-sway-bar-end-links-for-honda-civic-12-15-mini-cooper-r56-06-13.html | M16: 0 | N16: fapomoto
A17: 16 | B17: p0205 | C17: PZ283010 | D17: Chassis | E17: Front Stabilizer Sway Bar End Links For Chevrolet Camaro 10-15 Honda Civic 16-21 | F17: 255 | G17: 0 | H17: =ROUND(F17*(1-G17),2) | I17: 0 | J17: =ROUND(H17*I17,2) | K17: https://fapomoto.pl/produkty/p0205-pz283010-front-stabilizer-sway-bar-end-links-for-chevrolet-camaro-10-15-honda-civic-16-21.html | L17: https://cdn.shopify.com/s/files/1/0764/7258/2395/files/PZ283010_3.jpg?v=1754384294 | M17: 8 | N17: fapomoto
A18: 17 | B18: p0207 | C18: PZ292510 | D18: Chassis | E18: Front Stabilizer Sway Bar End Links For Hyundai Veloster 12-17 | F18: 255 | G18: 0 | H18: =ROUND(F18*(1-G18),2) | I18: 0 | J18: =ROUND(H18*I18,2) | K18: https://fapomoto.pl/produkty/p0207-pz292510-front-stabilizer-sway-bar-end-links-for-hyundai-veloster-12-17.html | L18: https://cdn.shopify.com/s/files/1/0764/7258/2395/files/PZ292510_4.jpg?v=1754384284 | M18: 8 | N18: fapomoto
A19: 18 | B19: p0208 | C19: PZ292710 | D19: Chassis | E19: Front Stabilizer Sway Bar End Links For Honda CRV CR-V RE 07-11 | F19: 255 | G19: 0 | H19: =ROUND(F19*(1-G19),2) | I19: 0 | J19: =ROUND(H19*I19,2) | K19: https://fapomoto.pl/produkty/p0208-pz292710-front-stabilizer-sway-bar-end-links-for-honda-crv-cr-v-re-07-11.html | L19: https://cdn.shopify.com/s/files/1/0764/7258/2395/files/PZ292710_3.jpg?v=1754384129 | M19: 8 | N19: fapomoto
A20: 19 | B20: p0209 | C20: PZ293010 | D20: Chassis | E20: Front Stabilizer Sway Bar End Links For Volkswagen Jetta MK5 MK6 FWD 06-17 | F20: 260 | G20: 0 | H20: =ROUND(F20*(1-G20),2) | I20: 0 | J20: =ROUND(H20*I20,2) | K20: https://fapomoto.pl/produkty/p0209-pz293010-front-stabilizer-sway-bar-end-links-for-volkswagen-jetta-mk5-mk6-fwd-06-17.html | M20: 0 | N20: fapomoto
A21: 20 | B21: p0593 | C21: PZ701210 | D21: Chassis | E21: FAPO 2 Pcs of Rear Toe Control Arm for Nissan 240SX/200SX S14/S15 1995-2002 PZ701210 | F21: 421 | G21: 0 | H21: =ROUND(F21*(1-G21),2) | I21: 0 | J21: =ROUND(H21*I21,2) | K21: https://fapomoto.pl/produkty/p0593-pz701210-fapo-2-pcs-of-rear-toe-control-arm-for-nissan-240sx-200sx-s14-s15-1995-2002-pz701210.html | L21: https://cdn.shopify.com/s/files/1/0764/7258/2395/files/DSC04426.jpg?v=1773976789 | M21: 6 | N21: fapomoto
A22: 21 | B22: p0627 | C22: 420071149261290374810320042920 | D22: Coilovers | E22: Open Box Special:32-Level Damping Coilover for Pontiac G8 2008-2009 sedan & Holden Caprice 3rd Gen VM 2006-2013 PF008030 | F22: 2265 | G22: 0 | H22: =ROUND(F22*(1-G22),2) | I22: 0 | J22: =ROUND(H22*I22,2) | K22: https://fapomoto.pl/produkty/p0627-420071149261290374810320042920-open-box-special-32-level-damping-coilover-for-pontiac-g8-2008-2009-sedan-holden-caprice-3rd-gen.html | L22: https://cdn.shopify.com/s/files/1/0764/7258/2395/files/pf_1288fa20-0054-426a-b514-c819489d155f.jpg?v=1777514428 | M22: 9 | N22: fapomoto
A23: 22 | B23: p0376 | C23: AE92 | D23: Coilovers | E23: 32-Level Damping Coilover For Toyota Corolla 6th/7th Gen AE92/AE100/AE101 1987-2000 PF005520 | F23: 2596 | G23: 0 | H23: =ROUND(F23*(1-G23),2) | I23: 0 | J23: =ROUND(H23*I23,2) | K23: https://fapomoto.pl/produkty/p0376-ae92-32-level-damping-coilover-for-toyota-corolla-6th-7th-gen-ae92-ae100-ae101-1987-2000-pf005520.html | L23: https://cdn.shopify.com/s/files/1/0764/7258/2395/files/2.png?v=1768469956 | M23: 6 | N23: fapomoto
A24: 23 | B24: p0504 | C24: AE92 | D24: Coilovers | E24: 32-Level Damping Coilover For Toyota Corolla 6th/7th/8th Gen AE92/AE100/AE101/AE102/AE110/AE111 1987-2000 PF005530 | F24: 2643 | G24: 0 | H24: =ROUND(F24*(1-G24),2) | I24: 0 | J24: =ROUND(H24*I24,2) | K24: https://fapomoto.pl/produkty/p0504-ae92-32-level-damping-coilover-for-toyota-corolla-6th-7th-8th-gen-ae92-ae100-ae101-ae102-ae110-ae111-.html | L24: https://cdn.shopify.com/s/files/1/0764/7258/2395/files/1_cdddadd6-1f87-4c54-bba3-72e97ae0cdd4.png?v=1768459195 | M24: 8 | N24: fapomoto
A25: 24 | B25: p0047 | C25: AGT20 | D25: Coilovers | E25: Coilover for Scion TC 2011-2016 AGT20/Toyota Prius 2008-2015 PS065610 | F25: 1603 | G25: 0 | H25: =ROUND(F25*(1-G25),2) | I25: 0 | J25: =ROUND(H25*I25,2) | K25: https://fapomoto.pl/produkty/p0047-agt20-coilover-for-scion-tc-2011-2016-agt20-toyota-prius-2008-2015-ps065610.html | L25: https://cdn.shopify.com/s/files/1/0764/7258/2395/files/c1d7ced95303c5c1.jpg?v=1756719643 | M25: 6 | N25: fapomoto
A26: 25 | B26: p0362 | C26: CV36 | D26: Coilovers | E26: 32-Level Damping Coilover For Infiniti G35X AWD V36 / G37X AWD / Q60 AWD V36/CV36 PF008630 | F26: 2170 | G26: 0 | H26: =ROUND(F26*(1-G26),2) | I26: 0 | J26: =ROUND(H26*I26,2) | K26: https://fapomoto.pl/produkty/p0362-cv36-32-level-damping-coilover-for-infiniti-g35x-awd-v36-g37x-awd-q60-awd-v36-cv36-pf008630.html | L26: https://cdn.shopify.com/s/files/1/0764/7258/2395/files/best_coilover_under_1000_1000x_4a784f7a-7fc3-42ff-b556-80ef0005e0dc.jpg?v=1767160823 | M26: 1 | N26: fapomoto
A27: 26 | B27: p0339 | C27: CV36 | D27: Coilovers | E27: 32-Level Damping Coilover for 2003-2015 Infiniti G35X G37X M35X M45X Q40 Q60 AWD V36/CV36 PF008620 | F27: 2170 | G27: 0 | H27: =ROUND(F27*(1-G27),2) | I27: 0 | J27: =ROUND(H27*I27,2) | K27: https://fapomoto.pl/produkty/p0339-cv36-32-level-damping-coilover-for-2003-2015-infiniti-g35x-g37x-m35x-m45x-q40-q60-awd-v36-cv36-pf0086.html | L27: https://cdn.shopify.com/s/files/1/0764/7258/2395/files/best_coilover_under_1000_812c1f23-5ec3-4909-b464-f4ac42e7ec2f.jpg?v=1770709215 | M27: 1 | N27: fapomoto
A28: 27 | B28: p0231 | C28: ES300 | D28: Coilovers | E28: 32-Level Damping Coilover for 1992-2004 Toyota Camry Avalon Solara / Lexus ES300 PF035520 | F28: 2360 | G28: 0 | H28: =ROUND(F28*(1-G28),2) | I28: 0 | J28: =ROUND(H28*I28,2) | K28: https://fapomoto.pl/produkty/p0231-es300-32-level-damping-coilover-for-1992-2004-toyota-camry-avalon-solara-lexus-es300-pf035520.html | L28: https://cdn.shopify.com/s/files/1/0764/7258/2395/files/25035308.jpg?v=1758618922 | M28: 8 | N28: fapomoto
A29: 28 | B29: p0368 | C29: EX25 | D29: Coilovers | E29: 32-Level Damping Coilover For Infiniti EX25 / G37 Convertible V36 / Q60 Convertible CV36/V36 PF034730 | F29: 2360 | G29: 0 | H29: =ROUND(F29*(1-G29),2) | I29: 0 | J29: =ROUND(H29*I29,2) | K29: https://fapomoto.pl/produkty/p0368-ex25-32-level-damping-coilover-for-infiniti-ex25-g37-convertible-v36-q60-convertible-cv36-v36-pf03473.html | L29: https://cdn.shopify.com/s/files/1/0764/7258/2395/files/2.png?v=1768469956 | M29: 3 | N29: fapomoto
A30: 29 | B30: p0521 | C30: FR072010 | D30: Coilovers | E30: FAPO Front 2" Leveling Lift Strut Spacers For Toyota Tundra 2007-2021 | F30: 99 | G30: 0 | H30: =ROUND(F30*(1-G30),2) | I30: 0 | J30: =ROUND(H30*I30,2) | K30: https://fapomoto.pl/produkty/p0521-fr072010-fapo-front-2-leveling-lift-strut-spacers-for-toyota-tundra-2007-2021.html | L30: https://cdn.shopify.com/s/files/1/0764/7258/2395/files/FR072010_8.jpg?v=1768638745 | M30: 9 | N30: fapomoto
A31: 30 | B31: p0511 | C31: FR072510 | D31: Coilovers | E31: FAPO Front 2.5" Leveling Lift Strut Spacers For Toyota Tundra 2007-2021 | F31: 279 | G31: 0 | H31: =ROUND(F31*(1-G31),2) | I31: 0 | J31: =ROUND(H31*I31,2) | K31: https://fapomoto.pl/produkty/p0511-fr072510-fapo-front-2-5-leveling-lift-strut-spacers-for-toyota-tundra-2007-2021.html | L31: https://cdn.shopify.com/s/files/1/0764/7258/2395/files/FR072510_1.jpg?v=1768552713 | M31: 8 | N31: fapomoto
A32: 31 | B32: p0517 | C32: FR073010 | D32: Coilovers | E32: Share FAPO Front 3" Leveling Lift Strut Spacers For Toyota Tundra 2007-2021 | F32: 279 | G32: 0 | H32: =ROUND(F32*(1-G32),2) | I32: 0 | J32: =ROUND(H32*I32,2) | K32: https://fapomoto.pl/produkty/p0517-fr073010-share-fapo-front-3-leveling-lift-strut-spacers-for-toyota-tundra-2007-2021.html | L32: https://cdn.shopify.com/s/files/1/0764/7258/2395/files/FR073010_1.jpg?v=1768620151 | M32: 9 | N32: fapomoto
... A545: 544 | B545: p0298 | C545: PA291930 | D545: Off-Road | E545: 8-Stage Front 4-6 in Lift Shocks for 2007-2018 Jeep Wrangler PA291930 | F545: 705 | G545: 0 | H545: =ROUND(F545*(1-G545),2) | I545: 0 | J545: =ROUND(H545*I545,2) | K545: https://fapomoto.pl/produkty/p0298-pa291930-8-stage-front-4-6-in-lift-shocks-for-2007-2018-jeep-wrangler-pa291930.html | L545: https://cdn.shopify.com/s/files/1/0764/7258/2395/files/10_45.jpg?v=1760145971 | M545: 9 | N545: fapomoto
A546: 545 | B546: p0316 | C546: PA291950 | D546: Off-Road | E546: Front 9-Way Monotube Shocks for Jeep Wrangler JK 2007-2018 (4-6 in Lift) PA291950 | F546: 1745 | G546: 0 | H546: =ROUND(F546*(1-G546),2) | I546: 0 | J546: =ROUND(H546*I546,2) | K546: https://fapomoto.pl/produkty/p0316-pa291950-front-9-way-monotube-shocks-for-jeep-wrangler-jk-2007-2018-4-6-in-lift-pa291950.html | M546: 0 | N546: fapomoto
A547: 546 | B547: p0267 | C547: PA292110 | D547: Off-Road | E547: FAPO Rear 0-1 in Lift Shocks for 2005-2021 Nissan Frontier Terra PA292110 | F547: 515 | G547: 0 | H547: =ROUND(F547*(1-G547),2) | I547: 0 | J547: =ROUND(H547*I547,2) | K547: https://fapomoto.pl/produkty/p0267-pa292110-fapo-rear-0-1-in-lift-shocks-for-2005-2021-nissan-frontier-terra-pa292110.html | L547: https://cdn.shopify.com/s/files/1/0764/7258/2395/files/10_15.jpg?v=1760146317 | M547: 10 | N547: fapomoto
A548: 547 | B548: p0268 | C548: PA292111 | D548: Off-Road | E548: FAPO Rear 0-3.5 in Lift Shocks for 2005-2022 Nissan Frontier PA292111 | F548: 515 | G548: 0 | H548: =ROUND(F548*(1-G548),2) | I548: 0 | J548: =ROUND(H548*I548,2) | K548: https://fapomoto.pl/produkty/p0268-pa292111-fapo-rear-0-3-5-in-lift-shocks-for-2005-2022-nissan-frontier-pa292111.html | L548: https://cdn.shopify.com/s/files/1/0764/7258/2395/files/PA292111_4.jpg?v=1760146286 | M548: 17 | N548: fapomoto
A549: 548 | B549: p0299 | C549: PA292130 | D549: Off-Road | E549: 8-Stage Rear 0-1 in Lift Shocks for 2005-2021 Nissan Frontier Terra PA292130 | F549: 705 | G549: 0 | H549: =ROUND(F549*(1-G549),2) | I549: 0 | J549: =ROUND(H549*I549,2) | K549: https://fapomoto.pl/produkty/p0299-pa292130-8-stage-rear-0-1-in-lift-shocks-for-2005-2021-nissan-frontier-terra-pa292130.html | L549: https://cdn.shopify.com/s/files/1/0764/7258/2395/files/10_40.jpg?v=1760145952 | M549: 9 | N549: fapomoto
A550: 549 | B550: p0300 | C550: PA292131 | D550: Off-Road | E550: 8-Stage Rear 0-3.5 in Lift Shocks for 2005-2022 Nissan Frontier PA292131 | F550: 705 | G550: 0 | H550: =ROUND(F550*(1-G550),2) | I550: 0 | J550: =ROUND(H550*I550,2) | K550: https://fapomoto.pl/produkty/p0300-pa292131-8-stage-rear-0-3-5-in-lift-shocks-for-2005-2022-nissan-frontier-pa292131.html | L550: https://cdn.shopify.com/s/files/1/0764/7258/2395/files/PA292131_1.jpg?v=1759197339 | M550: 15 | N550: fapomoto
A551: 550 | B551: p0269 | C551: PA292410 | D551: Off-Road | E551: FAPO Rear 2-3 in Lift Shocks for 2003-2021 Toyota Land Cruiser Prado 4Runner FJ CRUISER PA292410 | F551: 563 | G551: 0 | H551: =ROUND(F551*(1-G551),2) | I551: 0 | J551: =ROUND(H551*I551,2) | K551: https://fapomoto.pl/produkty/p0269-pa292410-fapo-rear-2-3-in-lift-shocks-for-2003-2021-toyota-land-cruiser-prado-4runner-fj-cruiser-pa292410.html | L551: https://cdn.shopify.com/s/files/1/0764/7258/2395/files/PA292410_1_66b00163-af2c-4384-a674-2831790adef6.jpg?v=1760074784 | M551: 17 | N551: fapomoto
A552: 551 | B552: p0301 | C552: PA292430 | D552: Off-Road | E552: 8-Stage Rear 2-3 in Lift Shocks for 2003-2021 Toyota Land Cruiser Prado 4Runner FJ CRUISER PA292430 | F552: 705 | G552: 0 | H552: =ROUND(F552*(1-G552),2) | I552: 0 | J552: =ROUND(H552*I552,2) | K552: https://fapomoto.pl/produkty/p0301-pa292430-8-stage-rear-2-3-in-lift-shocks-for-2003-2021-toyota-land-cruiser-prado-4runner-fj-cruiser-pa292.html | L552: https://cdn.shopify.com/s/files/1/0764/7258/2395/files/PA292430_2.jpg?v=1759198206 | M552: 15 | N552: fapomoto
A553: 552 | B553: p0097 | C553: PA360610 | D553: Off-Road | E553: P1 Off-road Front Shock for JEEP WRANGLER JK two doors 2007-2018 3-4.5 in lift PA360610 | F553: 515 | G553: 0 | H553: =ROUND(F553*(1-G553),2) | I553: 0 | J553: =ROUND(H553*I553,2) | K553: https://fapomoto.pl/produkty/p0097-pa360610-p1-off-road-front-shock-for-jeep-wrangler-jk-two-doors-2007-2018-3-4-5-in-lift-pa360610.html | L553: https://cdn.shopify.com/s/files/1/0764/7258/2395/files/7423b917921c66ae.jpg?v=1760147038 | M553: 11 | N553: fapomoto
...

Sheet Warunki
A1: FAPO Polska - warunki do oferty
A3: Ceny | B3: Ceny w PLN według aktualnego katalogu FAPO Polska. Arkusz nie rozdziela automatycznie wartości netto/brutto.
A4: Kalkulacja | B4: Wpisz ilość i ewentualny rabat przy wybranych pozycjach. Wartość pozycji i suma oferty liczą się automatycznie.
A5: Gwarancja | B5: Standardowa gwarancja: 12 miesięcy. Dla kwalifikujących się produktów możliwe rozszerzenie do 24 miesięcy.
A6: Zwroty | B6: Zwrot wymaga wcześniejszej autoryzacji RA. Standardowo do 30 dni od doręczenia, zgodnie z polityką FAPO Polska.
A7: Realizacja | B7: Przetwarzanie zamówień zwykle 1-2 dni robocze. Dostawa po nadaniu zwykle 2-7 dni roboczych.
A8: Kontakt | B8: office@fapomoto.pl | info@fapomoto.pl
A9: Dane firmy | B9: FAPO Polska | ul. Bokserska 59 lok. 17, 02-690 Warszawa | NIP 9512184841 | REGON 141812444
